Workbook

Sheet 總覽
A1: 棲光小島｜美術清單
A2: 更新：2026-10-28。P0＝上架前一定要有；P1＝上架前最好有；P2＝上架後再補。黃色欄位（各分頁的「狀態」「備註」）由製作者更新，數量與完成數會自動計算。
A4: 類別 | B4: 內容 | C4: 項目數 | D4: 張數／套數 | E4: 已完成 | F4: 完成率 | G4: 最高優先度 | H4: 分頁
A5: A. 動物主圖 | B5: 40 種動物（台灣 21、日本 19），每個成長階段 1 張（正側面） | C5: =COUNTA('A 動物主圖'!$B$5:$B$46) | D5: =SUM('A 動物主圖'!$F$5:$F$46) | E5: =COUNTIF('A 動物主圖'!$Q$5:$Q$46,"已完成") | F5: =IF(C5=0,0,E5/C5) | G5: P0 | H5: A 動物主圖
A6: B. 動物動態 | B6: 分層部件＋網格骨架；同體型共用動作 | C6: =COUNTA('B 動物動態'!$B$5:$B$46) | D6: =SUM('B 動物動態'!$E$5:$E$46) | E6: =COUNTIF('B 動物動態'!$L$5:$L$46,"已完成") | F6: =IF(C6=0,0,E6/C6) | G6: P0 | H6: B 動物動態
A7: C. 望遠鏡全景 | B7: 棲地 × 時段（含選配） | C7: =COUNTA('C 望遠鏡全景'!$B$5:$B$20) | D7: =COUNTA('C 望遠鏡全景'!$B$5:$B$20) | E7: =COUNTIF('C 望遠鏡全景'!$I$5:$I$20,"已完成") | F7: =IF(C7=0,0,E7/C7) | G7: P0 | H7: C 望遠鏡全景
A8: D. 小島場景 | B8: 底圖＋修復工程疊圖（台灣 8、日本 6） | C8: =COUNTA('D 小島場景'!$D$5:$D$20) | D8: =COUNTA('D 小島場景'!$D$5:$D$20) | E8: =COUNTIF('D 小島場景'!$I$5:$I$20,"已完成") | F8: =IF(C8=0,0,E8/C8) | G8: P0 | H8: D 小島場景
A9: E. 小道具 | B9: 倒木、腳印、羽毛等 | C9: =COUNTA('E 小道具'!$A$5:$A$10) | D9: =COUNTA('E 小道具'!$A$5:$A$10) | E9: =COUNTIF('E 小道具'!$F$5:$F$10,"已完成") | F9: =IF(C9=0,0,E9/C9) | G9: P1 | H9: E 小道具
A10: F. 介面圖示 | B10: 貨幣、寶箱、環境音、頭像、選單 | C10: =COUNTA('F 介面圖示'!$B$5:$B$18) | D10: =COUNTA('F 介面圖示'!$B$5:$B$18) | E10: =COUNTIF('F 介面圖示'!$G$5:$G$18,"已完成") | F10: =IF(C10=0,0,E10/C10) | G10: P0 | H10: F 介面圖示
A11: G. 插圖與上架 | B11: App 圖示、Google Play、引導與攔截插圖 | C11: =COUNTA('G 插圖與上架'!$B$5:$B$18) | D11: =COUNTA('G 插圖與上架'!$B$5:$B$18) | E11: =COUNTIF('G 插圖與上架'!$E$5:$E$18,"已完成") | F11: =IF(C11=0,0,E11/C11) | G11: P0 | H11: G 插圖與上架
A12: H. 地圖 | B12: 世界地圖、3D 地圖貼圖 | C12: =COUNTA('H 地圖'!$A$5:$A$8) | D12: =COUNTA('H 地圖'!$A$5:$A$8) | E12: =COUNTIF('H 地圖'!$E$5:$E$8,"已完成") | F12: =IF(C12=0,0,E12/C12) | G12: P0 | H12: H 地圖
A13: 合計 | C13: =SUM(C5:C12) | D13: =SUM(D5:D12) | E13: =SUM(E5:E12) | F13: =IF(C13=0,0,E13/C13)
A15: 圖例
A16: 已完成 | B16: 已交圖並接進 App
A17: 製作中 | B17: 正在畫或正在接
A18: 待驗收 | B18: 已交圖，等實機檢查
A19: 暫代 | B19: 目前用程式畫或暫代圖
A20: 選配 | B20: 有需要再做
A21: 未開始 | B21: 還沒開始
A23: 綠色數字是公式（自動計算）；黃色欄位請填寫。

Sheet 共通規格
A1: 共通規格
A2: 所有美術都要遵守。每一項後面附上原因（多半是實際做過、踩過的破綻）。
A4: 項目 | B4: 規格 | C4: 說明／原因
A5: 氣氛 | B5: 安靜、療癒、溫暖、自然觀察（生態手冊感） | C5: 專注 App：不要搶眼的特效、不要閃爍；沒有抽卡、沒有稀有度。
A6: 畫風 | B6: 霧面黏土質感的 2D 圖（像 3D 渲染）：圓潤、柔和光影、低紋理 | C6: 不要指紋、不要高光反射、不要粗黑描邊。
A7: 色彩 | B7: 低彩度鼠尾草綠為主，動物本身的顏色可以較鮮明 | C7: 介面色票：底色 #FBF6EC、面板 #FFFDF8、主色 #638553、深綠 #4A6A42、鼠尾草 #8CA67A、暖黃 #F3C566、珊瑚 #E08A70、湖藍 #9CCFD3、木色 #C9A77C。
A8: 光源 | B8: 左上方暖色漫射光，低對比 | C8: 所有動物、場景一致，放在同一個畫面才不會打架。
A9: 動物視角 | B9: 正側面、頭朝右，四條腿（或兩隻腳）都看得到 | C9: 網格動畫需要正側面主圖；所有動物、所有成長階段都一樣。
A10: 動物比例 | B10: 可愛化（頭稍大、身體圓潤），但物種特徵要正確 | C10: 保育主題：玩家要認得出真實物種。不穿衣服、不擬人站立。
A11: 動物解析度 | B11: 製作主圖 1024×1024（動物本體寬約 850～950 px）；App 用 512 px（之後可改 768） | C11: 畫面上最大的是望遠鏡最後推近：A8s 約需 550 px、旗艦機約 770 px。詳細見「動物尺寸」分頁。
A12: 小尺寸辨識 | B12: 縮到 30～50 px 仍要一眼分辨種類 | C12: 專注紀錄的格子在月／年檢視只有 6～50 px。
A13: 禁止 | B13: 文字、浮水印、背景物件、地面陰影、玩具式關節 | C13: 地面陰影由程式加；讓 GPT 分開畫部件會把關節畫成插銷（見 B 動物動態）。
A14: 交件格式 | B14: 透明 PNG（sRGB），程式轉成 WebP | C14: 尺寸用 2 的倍數；向量圖示可以給 SVG。
A15: 去背 | B15: 深色、淺色背景各檢查一次，不能有白邊 | C15: 白底去背：遮罩先往內縮 2 px 再柔化 0.8 px。
... A21: 驗收 | B21: 一律用手機實際顯示的大小檢查（半尺寸貼圖），並在 Galaxy A8s 實機確認 | C21: 原尺寸看起來正常、縮小後才出現的白線和斷層最常被漏掉。

Sheet 動物尺寸
A1: 動物尺寸：各畫面實際需要的像素
A2: 手機實際像素＝畫面大小（CSS px）× 螢幕密度（Galaxy A8s 約 2.6 倍，旗艦機約 3～3.5 倍）。結論：製作主圖 1024，App 用 512（之後可改 768）。
A4: 出現的地方 | B4: 畫面上的大小（CSS px） | C4: A8s 實際需要（px） | D4: 旗艦機實際需要（px） | E4: 備註
A5: 望遠鏡最後鎖定、推近（最大） | B5: 約 200～220 | C5: 約 550 | D5: 約 700～770 | E5: 專注結束那一刻；決定主圖要多大
A6: 遇見動物的揭曉畫面 | B6: 170 | C6: 約 440 | D6: 約 600
A7: 動物卡 | B7: 140 | C7: 約 365 | D7: 約 490
A8: 結算卡片 | B8: 約 120 | C8: 約 315 | D8: 約 420
A9: 分享圖（輸出 1080 寬） | B9: 固定 | C9: 440 | D9: 440 | E9: 和手機無關
A10: 我的小島 | B10: 52～96 | C10: 約 250 | D10: 約 340
A11: 專注紀錄的格子 | B11: 6～50 | C11: 很小 | D11: 很小 | E11: 要能一眼認出種類
A13: 建議規格
A14: 項目 | B14: 規格 | C14: 說明
A15: 製作主圖 | B15: 1024×1024，動物本體寬約 850～950 px | C15: 所有部件、網格動態的唯一來源；之後裁切、局部重畫都要留解析度。GPT 一次畫 1024 剛好。
A16: App 貼圖（建議） | B16: 512 px | C16: A8s 幾乎看不出差別、容量最省（每隻網格 ≤120 KB）；旗艦機在望遠鏡推近那一刻稍微軟一點。
A17: App 貼圖（之後可選） | B17: 768 px | C17: 旗艦機推近也清楚；每隻容量約多 1.5～2 倍，40 隻約多 4～6 MB。主圖是 1024，可以直接重新輸出，不用重畫。
A18: 幼年、亞成年 | B18: 同一張畫布，本體約成年的 60%、80% | C18: 畫面上本來就比較小，不用另外畫大。

Sheet A 動物主圖
A1: A. 動物主圖（每個成長階段 1 張）
A2: 正側面、頭朝右；製作時 1024×1024 白底主圖，App 用 512×512 透明（腳底 y＝472，離下緣 40 px）。三個成長階段畫布一樣大：幼年約成年的 60%、亞成年約 80%，腳底同一條線。這張主圖同時是 B 動物動態的唯一像素來源。黃色欄位由製作者更新。保育等級來源：維基百科「臺灣保育物種列表」（整理自農業部、海洋委員會名錄），上架前要以農業部 114/2/7 版名錄 PDF 再核對。
A4: 編號 | B4: 代號 | C4: 名稱 | D4: 區域 | E4: 體型 | F4: 張數 | G4: 成長階段 | H4: 外型重點（給畫師／GPT） | I4: 望遠鏡全景 | J4: 活動時段 | K4: 出現方式 | L4: 保育等級（稀有度） | M4: 取得方式 | N4: 交圖批次 | O4: 優先度 | P4: 檔名 | Q4: 狀態 | R4: 備註
A5: 台灣（21 種）
A6: 1 | B6: black_bear | C6: 台灣黑熊 | D6: 台灣 | E6: 熊 | F6: 3 | G6: 幼年／亞成年／成年 | H6: 黑色毛、胸前白色 V 字斑、圓耳 | I6: 山地森林 | J6: 白天 | K6: 從遠處走過來 | L6: 第一級・瀕臨絕種 | M6: 修好「設立保育救傷站」 | N6: 2 | O6: P0 | P6: black_bear-0/1/2.png | Q6: 未開始
A7: 2 | B7: leopard_cat | C7: 石虎 | D7: 台灣 | E7: 貓科 | F7: 3 | G7: 幼年／亞成年／成年 | H7: 家貓大小、黃褐底色有黑斑、額頭兩條白紋、耳背白斑（已有主圖，作為全系列風格參考） | I7: 中低海拔森林 | J7: 晨昏 | K7: 從遠處走過來 | L7: 第一級・瀕臨絕種 | M7: 修好「修好森林觀察小屋」 | N7: 1 | O7: P0 | P7: leopard_cat-0/1/2.png | Q7: 製作中 | R7: 成年主圖、網格已完成（全系列的風格與規格參考）；幼年、亞成年未做
A8: 3 | B8: pangolin | C8: 穿山甲 | D8: 台灣 | E8: 穿山甲 | F8: 3 | G8: 幼年／亞成年／成年 | H8: 全身覆蓋褐色鱗片、尖嘴、長尾巴、短腿 | I8: 中低海拔森林 | J8: 夜晚 | K8: 從遠處走過來 | L8: 第二級・珍貴稀有 | M8: 修好「清出林間步道」 | N8: 1 | O8: P0 | P8: pangolin-0/1/2.png | Q8: 未開始
A9: 4 | B9: blue_magpie | C9: 台灣藍鵲 | D9: 台灣 | E9: 鳥 | F9: 3 | G9: 雛鳥／幼鳥／成鳥 | H9: 寶藍色身體、黑頭、紅嘴紅腳、非常長的白端尾羽 | I9: 中低海拔森林 | J9: 白天 | K9: 遠處飛 → 停到倒木上 | L9: 第三級・其他應予保育 | M9: 一開始就能找 | N9: 1 | O9: P0 | P9: blue_magpie-0/1/2.png | Q9: 未開始
A10: 5 | B10: pitta | C10: 八色鳥 | D10: 台灣 | E10: 鳥 | F10: 3 | G10: 雛鳥／幼鳥／成鳥 | H10: 綠背、藍色肩斑、黑色過眼線、橘黃腹部、紅色尾下覆羽，短尾 | I10: 中低海拔森林 | J10: 白天 | K10: 遠處飛 → 停到倒木上 | L10: 第二級・珍貴稀有 | M10: 修好「種回原生樹苗」 | N10: 1 | O10: P0 | P10: pitta-0/1/2.png | Q10: 未開始
A11: 6 | B11: mikado_pheasant | C11: 帝雉 | D11: 台灣 | E11: 雉雞 | F11: 1 | G11: 只有一種樣式 | H11: 雄鳥深藍紫光澤羽毛、紅色臉、尾羽有白色橫帶 | I11: 山地森林 | J11: 晨昏 | K11: 從遠處走過來 | L11: 第二級・珍貴稀有 | M11: 商店 1,200 金幣 | N11: 4 | O11: P1 | P11: mikado_pheasant-2.png | Q11: 未開始
A12: 7 | B12: swinhoe_pheasant | C12: 藍腹鷴 | D12: 台灣 | E12: 雉雞 | F12: 3 | G12: 雛鳥／幼鳥／成鳥 | H12: 雄鳥深藍身體、白色長尾羽、紅色臉部裸皮、白色冠羽 | I12: 中低海拔森林 | J12: 晨昏 | K12: 從遠處走過來 | L12: 第二級・珍貴稀有 | M12: 修好「恢復林下草叢」 | N12: 2 | O12: P0 | P12: swinhoe_pheasant-0/1/2.png | Q12: 未開始
A13: 8 | B13: marten | C13: 黃喉貂 | D13: 台灣 | E13: 貂、獴 | F13: 3 | G13: 幼年／亞成年／成年 | H13: 深褐近黑的細長身體、亮黃色喉嚨、長尾 | I13: 山地森林 | J13: 白天 | K13: 從遠處走過來 | L13: 第三級・其他應予保育 | M13: 修好「整理森林水源地」 | N13: 2 | O13: P0 | P13: marten-0/1/2.png | Q13: 未開始
A14: 9 | B14: hawk_eagle | C14: 熊鷹 | D14: 台灣 | E14: 猛禽 | F14: 3 | G14: 雛鳥／幼鳥／成鳥 | H14: 大型猛禽、褐色身體、胸腹有橫斑、頭後短冠羽、寬大的翅膀 | I14: 山地森林 | J14: 白天 | K14: 天空盤旋 → 降落 | L14: 第一級・瀕臨絕種 | M14: 修好「搭建樹冠步道」 | N14: 2 | O14: P0 | P14: hawk_eagle-0/1/2.png | Q14: 未開始
A15: 10 | B15: fish_owl | C15: 黃魚鴞 | D15: 台灣 | E15: 貓頭鷹 | F15: 1 | G15: 只有一種樣式 | H15: 大型貓頭鷹、橘黃褐色、明顯耳羽、黃色眼睛、腳上沒有羽毛 | I15: 溪流 | J15: 夜晚 | K15: 夜裡先亮眼睛 → 停到倒木上 | L15: 第二級・珍貴稀有 | M15: 商店 90 寶石 | N15: 4 | O15: P1 | P15: fish_owl-2.png | Q15: 未開始 | R15: 程式原本寫第一級，已改成第二級
A16: 11 | B16: black_faced_spoonbill | C16: 黑面琵鷺 | D16: 台灣 | E16: 涉禽 | F16: 1 | G16: 只有一種樣式 | H16: 白色羽毛、黑色的臉、黑色湯匙狀長嘴、長腳（冬候鳥，曾文溪口） | I16: 濕地河口 | J16: 白天 | K16: 從遠處涉水走過來 | L16: 第一級・瀕臨絕種 | M16: 待定（新物種） | N16: 6 | O16: P2 | P16: black_faced_spoonbill-2.png | Q16: 未開始 | R16: 新增
A17: 12 | B17: yellow_tit | C17: 黃山雀 | D17: 台灣 | E17: 鳥 | F17: 1 | G17: 只有一種樣式 | H17: 黃色身體、黑色冠羽、黑色喉部、灰藍翅膀（台灣特有種） | I17: 山地森林 | J17: 白天 | K17: 遠處飛 → 停到倒木上 | L17: 第二級・珍貴稀有 | M17: 商店 70 寶石 | N17: 4 | O17: P1 | P17: yellow_tit-2.png | Q17: 未開始
A18: 13 | B18: hill_partridge | C18: 台灣山鷓鴣 | D18: 台灣 | E18: 雉雞 | F18: 1 | G18: 只有一種樣式 | H18: 圓胖的地棲鳥、褐色身體、白色喉部、紅色眼周（台灣特有） | I18: 中低海拔森林 | J18: 晨昏 | K18: 從遠處走過來 | L18: 第三級・其他應予保育 | M18: Plus 會員 | N18: 5 | O18: P2 | P18: hill_partridge-2.png | Q18: 未開始
A19: 14 | B19: clouded_leopard | C19: 台灣雲豹 | D19: 台灣 | E19: 貓科 | F19: 1 | G19: 只有一種樣式 | H19: 雲朵狀大斑塊、長尾、傳說感（可以畫得特別一點，例如淡淡的霧） | I19: 中低海拔森林 | J19: 夜晚 | K19: 從遠處走過來 | L19: 第一級・瀕臨絕種 | M19: Plus 會員 | N19: 5 | O19: P2 | P19: clouded_leopard-2.png | Q19: 未開始 | R19: 名錄列第一級；野外可能已滅絕（傳說）
A20: 15 | B20: eurasian_otter | C20: 歐亞水獺（金門） | D20: 台灣 | E20: 水獺 | F20: 1 | G20: 只有一種樣式 | H20: 深褐色流線身體、扁頭、粗長的尾巴、蹼足、濕亮的毛（金門） | I20: 溪流 | J20: 夜晚 | K20: 從遠處走過來（溪邊、湖邊） | L20: 第一級・瀕臨絕種 | M20: 待定（新物種） | N20: 6 | O20: P2 | P20: eurasian_otter-2.png | Q20: 未開始 | R20: 新增
A21: 16 | B21: formosan_salmon | C21: 櫻花鉤吻鮭 | D21: 台灣 | E21: 魚 | F21: 1 | G21: 只有一種樣式 | H21: 銀綠色身體、體側橢圓形雲斑，繁殖期帶粉紅色（七家灣溪） | I21: 溪流水下 | J21: 白天 | K21: 水裡由遠游近（新出現方式，程式待做） | L21: 第一級・瀕臨絕種 | M21: 待定（新物種） | N21: 6 | O21: P2 | P21: formosan_salmon-2.png | Q21: 未開始 | R21: 新增（台灣特有亞種）
A22: 17 | B22: green_turtle | C22: 綠蠵龜 | D22: 台灣 | E22: 海龜 | F22: 1 | G22: 只有一種樣式 | H22: 橢圓形背甲（橄欖綠帶褐色放射紋）、鰭狀前肢、小頭 | I22: 海洋 | J22: 白天 | K22: 浮出海面換氣，越游越近（新，程式待做） | L22: 第一級・瀕臨絕種 | M22: 待定（新物種） | N22: 6 | O22: P2 | P22: green_turtle-2.png | Q22: 未開始 | R22: 新增（海洋保育類）
A23: 18 | B23: white_dolphin | C23: 中華白海豚 | D23: 台灣 | E23: 海豚 | F23: 1 | G23: 只有一種樣式 | H23: 粉紅帶灰白斑點的身體、細長的嘴、三角形背鰭（台灣西部沿岸） | I23: 海洋 | J23: 白天 | K23: 遠方躍出海面，越來越近（新，程式待做） | L23: 第一級・瀕臨絕種 | M23: 待定（新物種） | N23: 6 | O23: P2 | P23: white_dolphin-2.png | Q23: 未開始 | R23: 新增（海洋保育類，台灣亞種）
A24: 19 | B24: broad_tailed_swallowtail | C24: 寬尾鳳蝶 | D24: 台灣 | E24: 蝴蝶 | F24: 1 | G24: 只有一種樣式 | H24: 黑色翅膀、後翅有寬大的尾突與紅色斑紋（台灣特有種） | I24: 山地森林 | J24: 白天 | K24: 飛舞，最後停到花上（新，程式待做） | L24: 第一級・瀕臨絕種 | M24: 待定（新物種） | N24: 6 | O24: P2 | P24: broad_tailed_swallowtail-2.png | Q24: 未開始 | R24: 新增（台灣特有種）
A25: 20 | B25: farmland_tree_frog | C25: 諸羅樹蛙 | D25: 台灣 | E25: 蛙 | F25: 1 | G25: 只有一種樣式 | H25: 翠綠色背部、白色腹部、體側白線、指端吸盤（台灣特有種，雲嘉南平地） | I25: 中低海拔森林 | J25: 夜晚 | K25: 夜裡先聽到叫聲、看到眼睛（同貓頭鷹） | L25: 第二級・珍貴稀有 | M25: 待定（新物種） | N25: 6 | O25: P2 | P25: farmland_tree_frog-2.png | Q25: 未開始 | R25: 新增（台灣特有種）
A26: 21 | B26: formosan_flying_fox | C26: 台灣狐蝠 | D26: 台灣 | E26: 蝙蝠 | F26: 1 | G26: 只有一種樣式 | H26: 大型蝙蝠、狐狸臉、金褐色頸毛、黑色膜翼（綠島、龜山島） | I26: 南方島嶼 | J26: 夜晚 | K26: 夜空中飛，最後倒掛在樹枝上（同猛禽盤旋） | L26: 第一級・瀕臨絕種 | M26: 待定（新物種） | N26: 6 | O26: P2 | P26: formosan_flying_fox-2.png | Q26: 未開始 | R26: 新增
A27: 日本（19 種）
A28: 1 | B28: iriomote_cat | C28: 西表山貓 | D28: 日本 | E28: 貓科 | F28: 3 | G28: 幼年／亞成年／成年 | H28: 深褐色帶斑點、耳背白斑、尾巴較粗短 | I28: 南方島嶼 | J28: 夜晚 | K28: 從遠處走過來 | L28: 絕滅危懼 IA 類（CR）｜特別天然紀念物・國內稀少種 | M28: 一開始就能找 | N28: 3 | O28: P1 | P28: iriomote_cat-0/1/2.png | Q28: 未開始 | R28: 紅色名錄 2020
A29: 2 | B29: tsushima_cat | C29: 對馬山貓 | D29: 日本 | E29: 貓科 | F29: 3 | G29: 幼年／亞成年／成年 | H29: 對馬的石虎：外型近似石虎、額頭白紋，毛色略深 | I29: 里山 | J29: 夜晚 | K29: 從遠處走過來 | L29: 絕滅危懼 IA 類（CR）｜天然紀念物・國內稀少種 | M29: 修好「疏伐過密的竹林」 | N29: 3 | O29: P1 | P29: tsushima_cat-0/1/2.png | Q29: 未開始 | R29: 紅色名錄 2020
A30: 3 | B30: amami_rabbit | C30: 奄美黑兔 | D30: 日本 | E30: 兔 | F30: 1 | G30: 只有一種樣式 | H30: 深褐色短毛、耳朵和腳都很短、圓胖身體（奄美大島、德之島特有） | I30: 南方島嶼 | J30: 夜晚 | K30: 夜裡從遠處跳過來 | L30: 絕滅危懼 IB 類（EN）｜特別天然紀念物・國內稀少種 | M30: 待定（新物種） | N30: 6 | O30: P2 | P30: amami_rabbit-2.png | Q30: 未開始 | R30: 新增；紅色名錄 2020
A31: 4 | B31: japanese_serow | C31: 日本鬣羚 | D31: 日本 | E31: 山羊 | F31: 3 | G31: 幼年／亞成年／成年 | H31: 灰黑色、頸部有鬃毛、短角、常站在岩石上 | I31: 山地森林 | J31: 晨昏 | K31: 從遠處走過來 | L31: 紅色名錄未列｜特別天然紀念物 | M31: 修好「清出杉林小徑」 | N31: 3 | O31: P1 | P31: japanese_serow-0/1/2.png | Q31: 未開始 | R31: 全國未列入紅色名錄，但是代表性的特別天然紀念物
A32: 5 | B32: bonin_flying_fox | C32: 小笠原狐蝠 | D32: 日本 | E32: 蝙蝠 | F32: 1 | G32: 只有一種樣式 | H32: 大型蝙蝠、全身深褐、頸部帶銀灰色毛、黑色膜翼（小笠原特有） | I32: 南方島嶼 | J32: 夜晚 | K32: 夜空中飛，最後倒掛在樹枝上（同猛禽盤旋） | L32: 絕滅危懼 IA 類（CR）｜天然紀念物・國內稀少種 | M32: 待定（新物種） | N32: 6 | O32: P2 | P32: bonin_flying_fox-2.png | Q32: 未開始 | R32: 新增；紅色名錄 2020
A33: 6 | B33: toki | C33: 朱鷺 | D33: 日本 | E33: 涉禽 | F33: 1 | G33: 只有一種樣式 | H33: 白中帶淡粉紅（朱鷺色）的羽毛、紅色臉部裸皮、黑色下彎長嘴、後腦冠羽 | I33: 里山 | J33: 白天 | K33: 從遠處涉水走過來 | L33: 絕滅危懼 IB 類（EN）｜特別天然紀念物・國內稀少種 | M33: 待定（新物種） | N33: 6 | O33: P2 | P33: toki-2.png | Q33: 未開始 | R33: 新增；第 5 次從 CR 降為 EN（佐渡野生約 576 隻）
A34: 7 | B34: red_crowned_crane | C34: 丹頂鶴 | D34: 日本 | E34: 涉禽 | F34: 1 | G34: 只有一種樣式 | H34: 白色身體、頭頂紅色、黑色頸部與次級飛羽、長腳（北海道釧路濕原） | I34: 濕地河口 | J34: 白天 | K34: 從遠處涉水走過來 | L34: 準絕滅危懼（NT）｜特別天然紀念物・國內稀少種 | M34: 待定（新物種） | N34: 6 | O34: P2 | P34: red_crowned_crane-2.png | Q34: 未開始 | R34: 新增；第 5 次從 VU 降為 NT（已不算瀕危）
A35: 8 | B35: oriental_stork | C35: 東方白鸛 | D35: 日本 | E35: 涉禽 | F35: 1 | G35: 只有一種樣式 | H35: 白色身體、黑色飛羽、粗長的黑嘴、紅色眼周與腳（兵庫豐岡） | I35: 里山 | J35: 白天 | K35: 從遠處涉水走過來 | L35: 絕滅危懼 IB 類（EN）｜特別天然紀念物・國內稀少種 | M35: 待定（新物種） | N35: 6 | O35: P2 | P35: oriental_stork-2.png | Q35: 未開始 | R35: 新增；第 5 次從 CR 降為 EN
A36: 9 | B36: okinawa_rail | C36: 山原秧雞 | D36: 日本 | E36: 雉雞 | F36: 1 | G36: 只有一種樣式 | H36: 橄欖褐色背部、黑白橫紋的腹部、紅色的嘴和腳、不會飛 | I36: 南方島嶼 | J36: 晨昏 | K36: 從遠處走過來 | L36: 絕滅危懼 IA 類（CR）｜天然紀念物・國內稀少種 | M36: 待定（新物種） | N36: 6 | O36: P2 | P36: okinawa_rail-2.png | Q36: 未開始 | R36: 新增；沖繩北部特有、不會飛
A37: 10 | B37: okinawa_woodpecker | C37: 野口啄木鳥 | D37: 日本 | E37: 鳥 | F37: 3 | G37: 雛鳥／幼鳥／成鳥 | H37: 全身深紅褐色、頭頂紅色（雄鳥）、啄木鳥姿態 | I37: 南方島嶼 | J37: 白天 | K37: 遠處飛 → 停到倒木上 | L37: 絕滅危懼 IB 類（EN）｜特別天然紀念物・國內稀少種 | M37: 一開始就能找 | N37: 3 | O37: P1 | P37: okinawa_woodpecker-0/1/2.png | Q37: 未開始 | R37: 第 5 次從 CR 降為 EN
A38: 11 | B38: ptarmigan | C38: 雷鳥 | D38: 日本 | E38: 雉雞 | F38: 3 | G38: 雛鳥／幼鳥／成鳥 | H38: 夏羽褐色斑駁、眼上紅色肉冠、腳有羽毛（冬羽全白可之後再做） | I38: 高山 | J38: 白天 | K38: 從遠處走過來 | L38: 絕滅危懼 IB 類（EN）｜特別天然紀念物・國內稀少種 | M38: 修好「復原里山梯田」 | N38: 3 | O38: P1 | P38: ptarmigan-0/1/2.png | Q38: 未開始
A39: 12 | B39: blakiston_owl | C39: 毛腿魚鴞 | D39: 日本 | E39: 貓頭鷹 | F39: 3 | G39: 雛鳥／幼鳥／成鳥 | H39: 世界最大的貓頭鷹之一、褐色斑紋、寬大耳羽、黃眼 | I39: 溪流 | J39: 夜晚 | K39: 夜裡先亮眼睛 → 停到倒木上 | L39: 絕滅危懼 IB 類（EN）｜天然紀念物・國內稀少種 | M39: 修好「修好山中小屋」 | N39: 3 | O39: P1 | P39: blakiston_owl-0/1/2.png | Q39: 未開始 | R39: 第 5 次從 CR 降為 EN
A40: 13 | B40: steller_eagle | C40: 虎頭海鵰 | D40: 日本 | E40: 猛禽 | F40: 3 | G40: 雛鳥／幼鳥／成鳥 | H40: 巨大的橘黃色嘴、深褐色身體、白色肩羽與白尾 | I40: 溪流 | J40: 白天 | K40: 天空盤旋 → 降落 | L40: 絕滅危懼 II 類（VU）｜天然紀念物・國內稀少種 | M40: 修好「恢復清澈溪流」 | N40: 3 | O40: P1 | P40: steller_eagle-0/1/2.png | Q40: 未開始
A41: 14 | B41: golden_eagle | C41: 金鵰 | D41: 日本 | E41: 猛禽 | F41: 1 | G41: 只有一種樣式 | H41: 大型深褐色猛禽、後頸金黃色、腳有羽毛 | I41: 高山 | J41: 白天 | K41: 天空盤旋 → 降落 | L41: 絕滅危懼 IB 類（EN）｜天然紀念物・國內稀少種 | M41: 待定（新物種） | N41: 6 | O41: P2 | P41: golden_eagle-2.png | Q41: 未開始 | R41: 新增
...

Sheet B 動物動態
A1: B. 動物動態（分層部件＋網格骨架）
A2: 規範：docs/規格-動物動態網格.md（不用 Rive／Spine）。每個成長階段各一套部件；同體型共用骨架與動作（見 B-1）。流程：主圖 → 剝層圖（GPT 一次只改一處）→ 切部件 → 網格與權重 → 半尺寸離線檢查 → A8s 實機檢查 → 輸出。
A4: 編號 | B4: 代號 | C4: 名稱 | D4: 體型 | E4: 套數（成長階段） | F4: 剝層圖（每套） | G4: 額外姿勢 | H4: 動作 | I4: 容量目標（每套） | J4: 交圖批次 | K4: 優先度 | L4: 狀態 | M4: 備註
A5: 台灣（21 種）
A6: 1 | B6: black_bear | C6: 台灣黑熊 | D6: 熊 | E6: 3 | F6: 同貓科 | G6: — | H6: 待機、張望、低頭聞、坐下、走路 | I6: ≤ 120 KB | J6: 2 | K6: P0 | L6: 未開始
A7: 2 | B7: leopard_cat | C7: 石虎 | D7: 貓科 | E7: 3 | F7: E1 拿掉近側兩條腿；E3 拿掉頭；E4 拿掉兩隻耳朵；E5 閉眼；E7 頭轉向鏡頭 | G7: — | H7: 待機呼吸、張望、低頭聞、甩尾、耳朵抖、眨眼、張嘴、走路（定格每秒 8 格） | I7: ≤ 120 KB | J7: 1 | K7: P0 | L7: 製作中 | M7: 成年完成；目前未壓縮 460 KB 要壓到 ≤120 KB；後腿之間一小撮淺色未解；幼年、亞成年未做
A8: 3 | B8: pangolin | C8: 穿山甲 | D8: 穿山甲 | E8: 3 | F8: 同貓科 | G8: — | H8: 待機、低頭聞、甩尾、走路（選配：捲成球） | I8: ≤ 120 KB | J8: 1 | K8: P0 | L8: 未開始
A9: 4 | B9: blue_magpie | C9: 台灣藍鵲 | D9: 鳥 | E9: 3 | F9: 拿掉近側翅膀；拿掉頭；閉眼；拿掉近側腳；頭轉向鏡頭 | G9: 飛行姿勢 1 張 | H9: 待機、跳兩步、低頭啄、理羽毛、歪頭、眨眼、拍翅；另需「飛行姿勢」1 張 | I9: ≤ 120 KB | J9: 1 | K9: P0 | L9: 未開始
A10: 5 | B10: pitta | C10: 八色鳥 | D10: 鳥 | E10: 3 | F10: 拿掉近側翅膀；拿掉頭；閉眼；拿掉近側腳；頭轉向鏡頭 | G10: 飛行姿勢 1 張 | H10: 待機、跳兩步、低頭啄、理羽毛、歪頭、眨眼、拍翅；另需「飛行姿勢」1 張 | I10: ≤ 120 KB | J10: 1 | K10: P0 | L10: 未開始
A11: 6 | B11: mikado_pheasant | C11: 帝雉 | D11: 雉雞 | E11: 1 | F11: 同鳥 | G11: — | H11: 待機、走路、低頭啄、抬頭張望、眨眼 | I11: ≤ 120 KB | J11: 4 | K11: P1 | L11: 未開始
A12: 7 | B12: swinhoe_pheasant | C12: 藍腹鷴 | D12: 雉雞 | E12: 3 | F12: 同鳥 | G12: — | H12: 待機、走路、低頭啄、抬頭張望、眨眼 | I12: ≤ 120 KB | J12: 2 | K12: P0 | L12: 未開始
A13: 8 | B13: marten | C13: 黃喉貂 | D13: 貂、獴 | E13: 3 | F13: 同貓科 | G13: — | H13: 待機、站起來張望、低頭聞、甩尾、走路 | I13: ≤ 120 KB | J13: 2 | K13: P0 | L13: 未開始
A14: 9 | B14: hawk_eagle | C14: 熊鷹 | D14: 猛禽 | E14: 3 | F14: 同鳥 | G14: 展翅盤旋 1 張 | H14: 待機、張望、展翅；另需「飛行姿勢（展翅盤旋）」1 張 | I14: ≤ 120 KB | J14: 2 | K14: P0 | L14: 未開始
A15: 10 | B15: fish_owl | C15: 黃魚鴞 | D15: 貓頭鷹 | E15: 1 | F15: 拿掉頭；閉眼；拿掉耳羽；頭轉向鏡頭 | G15: — | H15: 待機、大角度轉頭、眨眼、縮成一團（發光眼睛由程式畫） | I15: ≤ 120 KB | J15: 4 | K15: P1 | L15: 未開始
A16: 11 | B16: black_faced_spoonbill | C16: 黑面琵鷺 | D16: 涉禽 | E16: 1 | F16: 同鳥 | G16: 飛行姿勢 1 張（選配） | H16: 待機、涉水走、低頭左右掃嘴覓食、理羽毛 | I16: ≤ 120 KB | J16: 6 | K16: P2 | L16: 未開始
A17: 12 | B17: yellow_tit | C17: 黃山雀 | D17: 鳥 | E17: 1 | F17: 拿掉近側翅膀；拿掉頭；閉眼；拿掉近側腳；頭轉向鏡頭 | G17: 飛行姿勢 1 張 | H17: 待機、跳兩步、低頭啄、理羽毛、歪頭、眨眼、拍翅；另需「飛行姿勢」1 張 | I17: ≤ 120 KB | J17: 4 | K17: P1 | L17: 未開始
A18: 13 | B18: hill_partridge | C18: 台灣山鷓鴣 | D18: 雉雞 | E18: 1 | F18: 同鳥 | G18: — | H18: 待機、走路、低頭啄、抬頭張望、眨眼 | I18: ≤ 120 KB | J18: 5 | K18: P2 | L18: 未開始
A19: 14 | B19: clouded_leopard | C19: 台灣雲豹 | D19: 貓科 | E19: 1 | F19: E1 拿掉近側兩條腿；E3 拿掉頭；E4 拿掉兩隻耳朵；E5 閉眼；E7 頭轉向鏡頭 | G19: — | H19: 待機呼吸、張望、低頭聞、甩尾、耳朵抖、眨眼、張嘴、走路（定格每秒 8 格） | I19: ≤ 120 KB | J19: 5 | K19: P2 | L19: 未開始
... A26: 21 | B26: formosan_flying_fox | C26: 台灣狐蝠 | D26: 蝙蝠 | E26: 1 | F26: 頭轉向鏡頭（另畫倒掛、飛行姿勢） | G26: 飛行（展翼）、倒掛各 1 張 | H26: 飛行拍翼、倒掛時收翼、轉頭 | I26: ≤ 120 KB | J26: 6 | K26: P2 | L26: 未開始
A27: 日本（19 種）
A28: 1 | B28: iriomote_cat | C28: 西表山貓 | D28: 貓科 | E28: 3 | F28: E1 拿掉近側兩條腿；E3 拿掉頭；E4 拿掉兩隻耳朵；E5 閉眼；E7 頭轉向鏡頭 | G28: — | H28: 待機呼吸、張望、低頭聞、甩尾、耳朵抖、眨眼、張嘴、走路（定格每秒 8 格） | I28: ≤ 120 KB | J28: 3 | K28: P1 | L28: 未開始
A29: 2 | B29: tsushima_cat | C29: 對馬山貓 | D29: 貓科 | E29: 3 | F29: E1 拿掉近側兩條腿；E3 拿掉頭；E4 拿掉兩隻耳朵；E5 閉眼；E7 頭轉向鏡頭 | G29: — | H29: 待機呼吸、張望、低頭聞、甩尾、耳朵抖、眨眼、張嘴、走路（定格每秒 8 格） | I29: ≤ 120 KB | J29: 3 | K29: P1 | L29: 未開始
A30: 3 | B30: amami_rabbit | C30: 奄美黑兔 | D30: 兔 | E30: 1 | F30: 同貓科 | G30: — | H30: 待機、鼻子抽動、跳、低頭吃草、坐起張望 | I30: ≤ 120 KB | J30: 6 | K30: P2 | L30: 未開始
A31: 4 | B31: japanese_serow | C31: 日本鬣羚 | D31: 山羊 | E31: 3 | F31: 同貓科＋拿掉鬃毛 | G31: — | H31: 待機、張望、低頭吃草、甩耳、走路 | I31: ≤ 120 KB | J31: 3 | K31: P1 | L31: 未開始
A32: 5 | B32: bonin_flying_fox | C32: 小笠原狐蝠 | D32: 蝙蝠 | E32: 1 | F32: 頭轉向鏡頭（另畫倒掛、飛行姿勢） | G32: 飛行（展翼）、倒掛各 1 張 | H32: 飛行拍翼、倒掛時收翼、轉頭 | I32: ≤ 120 KB | J32: 6 | K32: P2 | L32: 未開始
A33: 6 | B33: toki | C33: 朱鷺 | D33: 涉禽 | E33: 1 | F33: 同鳥 | G33: 飛行姿勢 1 張（選配） | H33: 待機、涉水走、低頭左右掃嘴覓食、理羽毛 | I33: ≤ 120 KB | J33: 6 | K33: P2 | L33: 未開始
A34: 7 | B34: red_crowned_crane | C34: 丹頂鶴 | D34: 涉禽 | E34: 1 | F34: 同鳥 | G34: 飛行姿勢 1 張（選配） | H34: 待機、涉水走、低頭左右掃嘴覓食、理羽毛 | I34: ≤ 120 KB | J34: 6 | K34: P2 | L34: 未開始
A35: 8 | B35: oriental_stork | C35: 東方白鸛 | D35: 涉禽 | E35: 1 | F35: 同鳥 | G35: 飛行姿勢 1 張（選配） | H35: 待機、涉水走、低頭左右掃嘴覓食、理羽毛 | I35: ≤ 120 KB | J35: 6 | K35: P2 | L35: 未開始
A36: 9 | B36: okinawa_rail | C36: 山原秧雞 | D36: 雉雞 | E36: 1 | F36: 同鳥 | G36: — | H36: 待機、走路、低頭啄、抬頭張望、眨眼 | I36: ≤ 120 KB | J36: 6 | K36: P2 | L36: 未開始
A37: 10 | B37: okinawa_woodpecker | C37: 野口啄木鳥 | D37: 鳥 | E37: 3 | F37: 拿掉近側翅膀；拿掉頭；閉眼；拿掉近側腳；頭轉向鏡頭 | G37: 飛行姿勢 1 張 | H37: 待機、跳兩步、低頭啄、理羽毛、歪頭、眨眼、拍翅；另需「飛行姿勢」1 張 | I37: ≤ 120 KB | J37: 3 | K37: P1 | L37: 未開始
A38: 11 | B38: ptarmigan | C38: 雷鳥 | D38: 雉雞 | E38: 3 | F38: 同鳥 | G38: — | H38: 待機、走路、低頭啄、抬頭張望、眨眼 | I38: ≤ 120 KB | J38: 3 | K38: P1 | L38: 未開始
A39: 12 | B39: blakiston_owl | C39: 毛腿魚鴞 | D39: 貓頭鷹 | E39: 3 | F39: 拿掉頭；閉眼；拿掉耳羽；頭轉向鏡頭 | G39: — | H39: 待機、大角度轉頭、眨眼、縮成一團（發光眼睛由程式畫） | I39: ≤ 120 KB | J39: 3 | K39: P1 | L39: 未開始
... A46: 19 | B46: sakhalin_taimen | C46: 哲羅魚（伊富魚） | D46: 魚 | E46: 1 | F46: 拿掉胸鰭 | G46: — | H46: 游動擺尾、停在水中、轉向 | I46: ≤ 120 KB | J46: 6 | K46: P2 | L46: 未開始

Sheet B-1 體型模板
A1: B-1. 體型模板（同體型共用骨架與動作，只換貼圖）
A2: 40 隻動物只有 20 種體型，每種體型做 1 套骨架、權重規則與動作。貓科已用石虎驗證；其他體型以第一隻實作確認後再定案。
A4: 體型 | B4: 代號 | C4: 適用動物 | D4: 圖層（部件） | E4: 剝層圖 | F4: 骨架 | G4: 動作 | H4: 狀態
A5: 貓科 | B5: cat | C5: 石虎、台灣雲豹、西表山貓、對馬山貓 | D5: 遠側後腳、遠側前腳、身體、尾巴 3 節、近側後腳、近側前腳、脖子、遠側耳、頭、張眼、閉眼、下巴、近側耳（硬切片 23 層 → 網格 12 層） | E5: E1 拿掉近側兩條腿；E3 拿掉頭；E4 拿掉兩隻耳朵；E5 閉眼；E7 頭轉向鏡頭 | F5: 21 根：身體、脖子、頭、兩耳、下巴、尾巴 3 節、四條腿各 3 節 | G5: 待機呼吸、張望、低頭聞、甩尾、耳朵抖、眨眼、張嘴、走路（定格每秒 8 格） | H5: 已驗證（石虎）
A6: 熊 | B6: bear | C6: 台灣黑熊 | D6: 同貓科；尾巴 1 節 | E6: 同貓科 | F6: 同貓科，尾巴 1 根 | G6: 待機、張望、低頭聞、坐下、走路 | H6: 待第一隻實作確認
A7: 山羊 | B7: goat | C7: 日本鬣羚 | D7: 同貓科＋角（跟頭）、鬃毛（跟脖子） | E7: 同貓科＋拿掉鬃毛 | F7: 同貓科 | G7: 待機、張望、低頭吃草、甩耳、走路 | H7: 待第一隻實作確認
A8: 貂 | B8: mustelid | C8: 黃喉貂 | D8: 同貓科；身體較長 | E8: 同貓科 | F8: 同貓科，身體可多 1 節 | G8: 待機、站起來張望、低頭聞、甩尾、走路 | H8: 待第一隻實作確認
A9: 穿山甲 | B9: pangolin | C9: 穿山甲 | D9: 同貓科；鱗片身體、長尾 | E9: 同貓科 | F9: 同貓科 | G9: 待機、低頭聞、甩尾、走路（選配：捲成球） | H9: 待第一隻實作確認
A10: 鳥 | B10: bird | C10: 台灣藍鵲、八色鳥、黃山雀、野口啄木鳥 | D10: 身體、頭、嘴、張眼、閉眼、近側翅膀、遠側翅膀、尾羽、近側腳、遠側腳 | E10: 拿掉近側翅膀；拿掉頭；閉眼；拿掉近側腳；頭轉向鏡頭 | F10: 約 12 根：身體、頭、嘴、兩翅、尾羽 2 節、兩腳各 2 節 | G10: 待機、跳兩步、低頭啄、理羽毛、歪頭、眨眼、拍翅；另需「飛行姿勢」1 張 | H10: 待第一隻實作確認
A11: 雉雞 | B11: pheasant | C11: 帝雉、藍腹鷴、台灣山鷓鴣、雷鳥、山原秧雞 | D11: 同鳥；尾羽較長（3 節） | E11: 同鳥 | F11: 同鳥，尾羽 3 節 | G11: 待機、走路、低頭啄、抬頭張望、眨眼 | H11: 待第一隻實作確認
A12: 猛禽 | B12: raptor | C12: 熊鷹、虎頭海鵰、金鵰 | D12: 同鳥；翅膀較大 | E12: 同鳥 | F12: 同鳥 | G12: 待機、張望、展翅；另需「飛行姿勢（展翅盤旋）」1 張 | H12: 待第一隻實作確認
A13: 貓頭鷹 | B13: owl | C13: 黃魚鴞、毛腿魚鴞 | D13: 身體、頭、耳羽、張眼、閉眼、近側翅膀、腳 | E13: 拿掉頭；閉眼；拿掉耳羽；頭轉向鏡頭 | F13: 約 8 根：身體、頭、兩耳羽、兩翅、兩腳 | G13: 待機、大角度轉頭、眨眼、縮成一團（發光眼睛由程式畫） | H13: 待第一隻實作確認
A14: 涉禽 | B14: wader | C14: 黑面琵鷺、朱鷺、丹頂鶴、東方白鸛 | D14: 同鳥＋長腳、長嘴 | E14: 同鳥 | F14: 同鳥，腳各 3 節、嘴 1 節 | G14: 待機、涉水走、低頭左右掃嘴覓食、理羽毛 | H14: 待第一隻實作確認
A15: 水獺 | B15: otter | C15: 歐亞水獺（金門） | D15: 同貓科；身體長、尾巴粗 | E15: 同貓科 | F15: 同貓科，身體多 1 節、尾巴 3 節 | G15: 待機、站起來張望、走路、游泳（另畫游泳姿勢） | H15: 待第一隻實作確認
... A24: 海鳥 | B24: seabird | C24: 短尾信天翁 | D24: 同鳥；翅膀很長 | E24: 同鳥 | F24: 同鳥 | G24: 待機、張望、滑翔、互相碰嘴；另需「展翅滑翔」1 張 | H24: 待第一隻實作確認

Sheet C 望遠鏡全景
A1: C. 專注畫面的望遠鏡全景（棲地 × 時段）
A2: 專注時上方圓形鏡片在橫向全景上左右搜尋、推近拉遠，動物專注一小段時間後在遠方出現、越來越近。全景照「棲地」共用，不照國家分。晨昏先用白天版調色（選配列）。規格見 C-1。
A4: 編號 | B4: 檔名 | C4: 棲地 | D4: 時段 | E4: 會用到的動物（晨昏的動物先用白天版） | F4: 尺寸 | G4: 交圖批次 | H4: 優先度 | I4: 狀態 | J4: 備註
A5: 1 | B5: pano-forest-low-day.webp | C5: 中低海拔森林 | D5: 白天 | E5: 石虎、台灣藍鵲、八色鳥、藍腹鷴、台灣山鷓鴣 | F5: 約 3000×1150 | G5: 1 | H5: P0 | I5: 暫代 | J5: 原型暫時用 focus-done.webp（白天山景）
A6: 2 | B6: pano-forest-low-night.webp | C6: 中低海拔森林 | D6: 夜晚 | E6: 穿山甲、台灣雲豹、諸羅樹蛙 | F6: 約 3000×1150 | G6: 1 | H6: P0 | I6: 暫代 | J6: 原型暫時把白天全景壓暗
A7: 3 | B7: pano-stream-day.webp | C7: 溪流 | D7: 白天 | E7: 虎頭海鵰 | F7: 約 3000×1150 | G7: 2 | H7: P1 | I7: 未開始
A8: 4 | B8: pano-stream-night.webp | C8: 溪流 | D8: 夜晚 | E8: 黃魚鴞、歐亞水獺（金門）、毛腿魚鴞、日本大山椒魚 | F8: 約 3000×1150 | G8: 2 | H8: P1 | I8: 未開始
A9: 5 | B9: pano-island-day.webp | C9: 南方島嶼（亞熱帶林） | D9: 白天 | E9: 山原秧雞、野口啄木鳥 | F9: 約 3000×1150 | G9: 3 | H9: P1 | I9: 未開始
A10: 6 | B10: pano-island-night.webp | C10: 南方島嶼（亞熱帶林） | D10: 夜晚 | E10: 台灣狐蝠、西表山貓、奄美黑兔、小笠原狐蝠、沖繩石川蛙 | F10: 約 3000×1150 | G10: 3 | H10: P1 | I10: 未開始
A11: 7 | B11: pano-forest-mountain-day.webp | C11: 山地森林（針葉林、較涼） | D11: 白天 | E11: 台灣黑熊、帝雉、黃喉貂、熊鷹、黃山雀、寬尾鳳蝶、日本鬣羚 | F11: 約 3000×1150 | G11: 4 | H11: P1 | I11: 未開始
A12: 8 | B12: pano-alpine-day.webp | C12: 高山（草原、岩壁） | D12: 白天 | E12: 雷鳥、金鵰 | F12: 約 3000×1150 | G12: 4 | H12: P1 | I12: 未開始
A13: 9 | B13: pano-satoyama-night.webp | C13: 里山 | D13: 夜晚 | E13: 對馬山貓 | F13: 約 3000×1150 | G13: 4 | H13: P1 | I13: 未開始
A14: 10 | B14: pano-satoyama-day.webp | C14: 里山 | D14: 白天 | E14: 朱鷺、東方白鸛 | F14: 約 3000×1150 | G14: 6 | H14: P2 | I14: 未開始 | J14: 日本新增物種用（朱鷺、東方白鸛：水田、溪邊）
A15: 11 | B15: pano-wetland-day.webp | C15: 濕地河口 | D15: 白天 | E15: 黑面琵鷺、丹頂鶴 | F15: 約 3000×1150 | G15: 6 | H15: P2 | I15: 未開始 | J15: 新增物種用（黑面琵鷺、丹頂鶴；丹頂鶴可加雪地版）
A16: 12 | B16: pano-ocean-day.webp | C16: 海洋（海面＋淺水下） | D16: 白天 | E16: 綠蠵龜、中華白海豚、短尾信天翁、赤蠵龜 | F16: 約 3000×1150 | G16: 6 | H16: P2 | I16: 未開始 | J16: 新增物種用；要看得到水下（綠蠵龜、中華白海豚、赤蠵龜、短尾信天翁）
A17: 13 | B17: pano-stream-under-day.webp | C17: 溪流水下 | D17: 白天 | E17: 櫻花鉤吻鮭、哲羅魚（伊富魚） | F17: 約 3000×1150 | G17: 6 | H17: P2 | I17: 未開始 | J17: 新增物種用（櫻花鉤吻鮭、哲羅魚）
A18: 14 | B18: pano-forest-low-dusk.webp | C18: 中低海拔森林 | D18: 晨昏 | E18: 石虎、藍腹鷴、台灣山鷓鴣 | F18: 約 3000×1150 | G18: 5 | H18: P2 | I18: 選配 | J18: 先用白天版加暖色調
A19: 15 | B19: pano-forest-mountain-dusk.webp | C19: 山地森林（針葉林、較涼） | D19: 晨昏 | E19: 帝雉、日本鬣羚 | F19: 約 3000×1150 | G19: 5 | H19: P2 | I19: 選配 | J19: 先用白天版加暖色調
A20: 16 | B20: pano-alpine-dusk.webp | C20: 高山（草原、岩壁） | D20: 晨昏 | E20: （之後新增的動物） | F20: 約 3000×1150 | G20: 5 | H20: P2 | I20: 選配 | J20: 先用白天版加暖色調

Sheet C-1 全景規格
A1: C-1. 望遠鏡全景規格
A2: 構圖與尺寸都和程式的座標對應，改之前先確認。
A4: 項目 | B4: 規格 | C4: 說明
A5: 尺寸 | B5: 約 3000 × 1150 px（約 2.6：1） | C5: 鏡片在手機上約 950 px 寬；全景放大 1.3 倍、再推近約 1.2 倍，圖高 1,150～1,400 px 才清楚。
A6: 構圖 | B6: 天空約佔上方 1/3；中間偏下（高度 55%～75%）是一片平坦地面 | C6: 動物在地面上走近、停下；猛禽在天空盤旋。
A7: 留白 | B7: 水平 62%、高度 59%～70% 附近保持乾淨 | C7: 這裡是動物最後停下、倒木擺放的位置（程式座標 SPOT＝62%, 70%）。
A8: 左右兩側 | B8: 可以放樹、岩石增加層次，但不要太多細節 | C8: 底圖結構太複雜會讓動物看不清楚。
A9: 夜晚版 | B9: 用白天版請 GPT 轉成夜景，構圖完全一樣 | C9: 動物出現的位置不用重新對。
A10: 晨昏 | B10: 先用白天版加暖色調處理，不另外畫
A11: GPT 限制 | B11: 一次最大約 1536 × 1024 | C11: 要分左右兩半畫、中間重疊一段再接，或由美術直接出大圖。
A12: 共用 | B12: 大廳的鏡片、結算頁的圖片都裁切同一張全景 | C12: 不用另外畫。
A13: 其他國家 | B13: 照棲地共用；全世界常見棲地 12～15 種 × 白天、夜晚 | C13: 總量上限約 24～30 張；地區特色用小的去背疊圖補（P2）。

Sheet D 小島場景
A1: D. 我的小島：場景與修復工程
A2: 2D 分層插畫：一張底圖＋每個工程一張去背疊圖（同畫布、完全對齊）。投入 25／50／75／100% 時物件依序出現。規格見 D-1。
A4: 區域 | B4: 順序 | C4: 工程代號 | D4: 工程 | E4: 需要點數 | F4: 完成後的樣子 | G4: 要交的圖 | H4: 優先度 | I4: 狀態 | J4: 備註
A5: 台灣・棲光森林 | B5: 0 | C5: — | D5: 初始（荒廢）＋底圖 | F5: 荒廢的森林：枯黃地面、倒木、落石 | G5: 底圖 1 張（直式） | H5: P0 | I5: 暫代 | J5: 目前用 forest.webp（1167×1347，GPT 畫的完成狀態）
A6: 台灣・棲光森林 | B6: 1 | C6: fo_trail | D6: 清出林間步道 | E6: 10 | F6: 搬開倒木與落石，步道可以走了 | G6: 去背疊圖 1 張（拆 2～4 個物件，依 25／50／75／100% 出現） | H6: P0 | I6: 未開始
A7: 台灣・棲光森林 | B7: 2 | C7: fo_saplings | D7: 種回原生樹苗 | E7: 430 | F7: 一排排小樹苗冒出新芽 | G7: 去背疊圖 1 張（拆 2～4 個物件，依 25／50／75／100% 出現） | H7: P0 | I7: 未開始
A8: 台灣・棲光森林 | B8: 3 | C8: fo_cabin | D8: 修好森林觀察小屋 | E8: 1300 | F8: 小屋亮起燈，可以安靜地觀察森林 | G8: 去背疊圖 1 張（拆 2～4 個物件，依 25／50／75／100% 出現） | H8: P0 | I8: 未開始
A9: 台灣・棲光森林 | B9: 4 | C9: fo_undergrowth | D9: 恢復林下草叢 | E9: 1850 | F9: 蕨類與草叢長回來，小動物有地方躲 | G9: 去背疊圖 1 張（拆 2～4 個物件，依 25／50／75／100% 出現） | H9: P0 | I9: 未開始
A10: 台灣・棲光森林 | B10: 5 | C10: fo_corridor | D10: 架設生態廊道 | E10: 2150 | F10: 動物可以安全穿越的綠色通道 | G10: 去背疊圖 1 張（拆 2～4 個物件，依 25／50／75／100% 出現） | H10: P0 | I10: 未開始
A11: 台灣・棲光森林 | B11: 6 | C11: fo_spring | D11: 整理森林水源地 | E11: 2450 | F11: 清澈的泉水流進小水池 | G11: 去背疊圖 1 張（拆 2～4 個物件，依 25／50／75／100% 出現） | H11: P0 | I11: 未開始
A12: 台灣・棲光森林 | B12: 7 | C12: fo_canopy | D12: 搭建樹冠步道 | E12: 2600 | F12: 高處的木棧道，看得到整片樹海 | G12: 去背疊圖 1 張（拆 2～4 個物件，依 25／50／75／100% 出現） | H12: P0 | I12: 未開始
A13: 台灣・棲光森林 | B13: 8 | C13: fo_rescue | D13: 設立保育救傷站 | E13: 2700 | F13: 受傷的動物在這裡被好好照顧 | G13: 去背疊圖 1 張（拆 2～4 個物件，依 25／50／75／100% 出現） | H13: P0 | I13: 未開始
A14: 日本・里山 | B14: 0 | C14: — | D14: 初始（荒廢）＋底圖 | F14: 荒廢的里山：倒下的杉木、乾涸的梯田 | G14: 底圖 1 張（直式） | H14: P1 | I14: 未開始
A15: 日本・里山 | B15: 1 | C15: jp_path | D15: 清出杉林小徑 | E15: 300 | F15: 倒下的杉木搬開了，小徑可以走了 | G15: 去背疊圖 1 張（拆 2～4 個物件，依 25／50／75／100% 出現） | H15: P1 | I15: 未開始
A16: 日本・里山 | B16: 2 | C16: jp_terrace | D16: 復原里山梯田 | E16: 800 | F16: 梯田重新灌水，青蛙和水鳥回來了 | G16: 去背疊圖 1 張（拆 2～4 個物件，依 25／50／75／100% 出現） | H16: P1 | I16: 未開始
A17: 日本・里山 | B17: 3 | C17: jp_hut | D17: 修好山中小屋 | E17: 1100 | F17: 小屋亮起燈，可以安靜地觀察里山 | G17: 去背疊圖 1 張（拆 2～4 個物件，依 25／50／75／100% 出現） | H17: P1 | I17: 未開始
A18: 日本・里山 | B18: 4 | C18: jp_bamboo | D18: 疏伐過密的竹林 | E18: 1300 | F18: 陽光照進林下，原生植物長回來 | G18: 去背疊圖 1 張（拆 2～4 個物件，依 25／50／75／100% 出現） | H18: P1 | I18: 未開始
A19: 日本・里山 | B19: 5 | C19: jp_stream | D19: 恢復清澈溪流 | E19: 1500 | F19: 溪水變清，魚群又游了回來 | G19: 去背疊圖 1 張（拆 2～4 個物件，依 25／50／75／100% 出現） | H19: P1 | I19: 未開始
A20: 日本・里山 | B20: 6 | C20: jp_rescue | D20: 設立野生動物保護站 | E20: 1600 | F20: 受傷的動物在這裡被好好照顧 | G20: 去背疊圖 1 張（拆 2～4 個物件，依 25／50／75／100% 出現） | H20: P1 | I20: 未開始

Sheet D-1 場景規格
A1: D-1. 小島場景規格
A4: 項目 | B4: 規格 | C4: 說明
A5: 方向 | B5: 2D 分層插畫（不做 3D 模型） | C5: 最省電、最適合直式手機、也最容易用 AI 輔助。
A6: 畫布 | B6: 底圖與每張疊圖同一個畫布大小、完全對齊 | C6: 目前底圖 1167×1347；正式版建議 1440×1664。
A7: 疊圖 | B7: 每個工程一張去背圖，裡面拆成 2～4 個物件圖層 | C7: 投入 25／50／75／100% 時依序出現（例如小屋：地板 → 牆 → 屋頂 → 亮燈）。
A8: 動物位置 | B8: 前景留 6 個站位不被樹擋住 | C8: 程式座標見 src/pages/Island.tsx 的 SPOTS。
A9: 地面 | B9: 從枯黃慢慢轉綠：可給 3 張地面色層（荒廢、一半、完成） | C9: 程式依修復進度交叉淡入。
A10: 放棄專注 | B10: 不用另外畫 | C10: 程式把畫面調灰。
A11: 完成演出 | B11: 全部工程完成後的夜晚與螢火蟲 | C11: 螢火蟲由程式畫；需要一張夜晚色調版（或由程式調色）。

Sheet E 小道具
A1: E. 望遠鏡畫面的小道具
A2: 風格同全景；去背 PNG。
A4: 項目 | B4: 代號 | C4: 用途 | D4: 規格 | E4: 優先度 | F4: 狀態 | G4: 備註
A5: 倒木 | B5: log | C5: 鳥、貓頭鷹最後停的地方（望遠鏡全景裡，跟著左右掃） | D5: 去背，寬約 800 px | E5: P1 | F5: 暫代 | G5: 目前程式畫
A6: 樹洞或枝頭暗影 | B6: owl_perch | C6: 貓頭鷹夜裡出現的地方（替代倒木） | D6: 去背，寬約 800 px | E6: P2 | F6: 選配
A7: 前景樹枝 | B7: branch | C7: 鳥停的枝頭（替代倒木） | D7: 去背，寬約 1200 px | E7: P2 | F7: 選配 | G7: 目前沒有用到
A8: 地區特色疊圖 | B8: region_overlay | C8: 共用全景上加一點地區特色（例如富士山輪廓、竹子） | D8: 去背，寬約 1500 px | E8: P2 | F8: 選配 | G8: 每個地區 1 張
A9: 腳印 | B9: footprint | C9: 動物被嚇跑後留下的腳印、發現新足跡的演出 | D9: 去背，256 px，鳥、獸各 1 種 | E9: P2 | F9: 未開始
A10: 羽毛 | B10: feather | C10: 鳥類被嚇跑後留下的羽毛 | D10: 去背，256 px | E10: P2 | F10: 未開始

Sheet F 介面圖示
A1: F. 介面圖示
A2: 黏土風格的圖示（金幣、寶石、寶箱）已完成，其餘照同一個風格。線條圖示（選單、按鈕）可以沿用現有的 lucide。
A4: 群組 | B4: 項目 | C4: 代號 | D4: 規格 | E4: 出現位置 | F4: 優先度 | G4: 狀態 | H4: 備註
A5: 貨幣 | B5: 金幣 | C5: coin | D5: 512 px 去背，置中 | E5: 錢包、商店、獎勵 | F5: P0 | G5: 已完成 | H5: src/assets/icons/coin.webp
A6: 貨幣 | B6: 寶石 | C6: gem | D6: 512 px 去背，置中 | E6: 錢包、商店、獎勵 | F6: P0 | G6: 已完成 | H6: src/assets/icons/gem.webp
A7: 寶箱 | B7: 木箱（每日挑戰）關閉 | C7: chest-wood | D7: 512 px 去背 | E7: 挑戰卡、開寶箱 | F7: P0 | G7: 已完成
A8: 寶箱 | B8: 綠寶石箱（新手任務）關閉 | C8: chest-green | D8: 512 px 去背 | E8: 新手任務、開寶箱 | F8: P0 | G8: 已完成
A9: 寶箱 | B9: 紫金箱（本月挑戰）關閉 | C9: chest-royal | D9: 512 px 去背 | E9: 本月挑戰、開寶箱 | F9: P0 | G9: 已完成
A10: 寶箱 | B10: 木箱 打開 | C10: chest-wood-open | D10: 512 px 去背，和關閉的對齊 | E10: 領過的挑戰、開寶箱的最後一格 | F10: P1 | G10: 未開始 | H10: 使用者有提供圖，但檔案沒有傳成功，要再傳一次
A11: 寶箱 | B11: 綠寶石箱 打開 | C11: chest-green-open | D11: 同上 | E11: 同上 | F11: P1 | G11: 未開始 | H11: 同上
A12: 寶箱 | B12: 紫金箱 打開 | C12: chest-royal-open | D12: 同上 | E12: 同上 | F12: P1 | G12: 未開始 | H12: 同上
A13: 貨幣 | B13: 修復點數 | C13: point | D13: 512 px 去背 | E13: 修復工程、結算 | F13: P2 | G13: 未開始 | H13: 目前用文字
A14: 環境音 | B14: 森林微風、林間鳥鳴、草叢蟲鳴、泉水潺潺、雨後滴答、夏夜森林、林間蛙鳴（7 個） | C14: sound_* | D14: 256 px 去背或 SVG | E14: 環境音選單、商店 | F14: P1 | G14: 未開始 | H14: 目前用 emoji
A15: 頭像 | B15: 葉子、小花、貝殼、太陽、月亮、水滴、蘑菇、星星（8 個） | C15: avatar_* | D15: 256 px 去背，圓形構圖 | E15: 設定、好友、選單 | F15: P1 | G15: 未開始 | H15: 目前用 emoji
A16: 選單 | B16: 大廳、我的小島、觀察圖鑑、任務、專注紀錄、商店、好友、時間守護、設定（9 個） | C16: nav_* | D16: SVG 線條圖示，24 px 網格 | E16: 左側選單 | F16: P2 | G16: 暫代 | H16: 目前用 lucide 線條圖示，可以沿用
A17: 其他 | B17: 望遠鏡、腳印、盾牌、鎖頭、暫停／播放／停止 | C17: icon_* | D17: SVG 線條圖示 | E17: 各處 | F17: P2 | G17: 暫代 | H17: 目前用 lucide 線條圖示，可以沿用
A18: 國旗 | B18: 台灣、日本（之後新地區） | C18: — | D18: 程式畫的 SVG | E18: 動物格子、地區切換 | F18: — | G18: 已完成 | H18: 不用畫

Sheet G 插圖與上架
A1: G. 插圖、App 圖示與上架素材
A4: 類別 | B4: 項目 | C4: 規格 | D4: 優先度 | E4: 狀態 | F4: 備註
A5: App | B5: App 圖示 | C5: 1024×1024；另附 Android 自適應圖示的前景（主體在中間 66%）＋背景色 | D5: P0 | E5: 暫代 | F5: 目前是舊的溫室主題小島
A6: App | B6: 啟動畫面 | C6: 圖示置中＋底色 #FBF6EC | D6: P0 | E6: 暫代
A7: App | B7: 通知小圖示 | C7: 24×24 dp 單色（白色＋透明）簡單輪廓 | D7: P0 | E7: 暫代 | F7: 目前是程式畫的望遠鏡，可以沿用
A8: Google Play | B8: 主題圖片（feature graphic） | C8: 1024×500 | D8: P0 | E8: 未開始 | F8: 上架必填
A9: Google Play | B9: 手機截圖 | C9: 直式 1080×1920 以上，6～8 張，可加標語框 | D9: P0 | E9: 未開始 | F9: 建議：大廳、望遠鏡專注、遇見動物、我的小島、觀察圖鑑地圖、專注紀錄、上週回顧、時間守護
A10: Google Play | B10: 商店圖示 | C10: 512×512 | D10: P0 | E10: 未開始 | F10: 可用 App 圖示
A11: 新手引導 | B11: 首頁大插圖、故事 3 張、第一次探索 1 張（共 5 張） | C11: 1080×1080 去背或滿版 | D11: P1 | E11: 暫代 | F11: 目前用動物圖拼湊
A12: 時間守護 | B12: 引導 4 頁的手機情境（問號、滑不完的動態、守護動物＋盾牌、上鎖的 App） | C12: 每張 600×1066（手機螢幕比例） | D12: P2 | E12: 暫代 | F12: 目前用程式畫，可以沿用
A13: 時間守護 | B13: 「先停一下」攔截畫面插圖 | C13: 1080×1080 去背 | D13: P1 | E13: 暫代 | F13: 目前用守護動物
A14: 深度專注 | B14: 「專注中」攔截畫面：動物在附近、被打擾 | C14: 1080×1080 去背 | D14: P1 | E14: 未開始
A15: 上週回顧 | B15: 7 頁的頁首插圖或底圖 | C15: 1080×600 | D15: P2 | E15: 未開始 | F15: 總時數、專注天數、最佳日、陪你最久、和前一週比、排名、總結卡
A16: 分享圖 | B16: 三種分享卡版型：單次專注、期間統計、上週回顧 | C16: 1080×1920 | D16: P2 | E16: 未開始
A17: 商店 | B17: Plus 會員介紹插圖 | C17: 1080×600 | D17: P2 | E17: 未開始 | F17: 要和金幣動物有區別
A18: 其他 | B18: WebView 太舊的提示頁 | C18: 600×600 | D18: P2 | E18: 未開始

Sheet H 地圖
A1: H. 地圖
A4: 項目 | B4: 檔案 | C4: 尺寸 | D4: 優先度 | E4: 狀態 | F4: 備註
A5: 區域切換的世界地圖 | B5: src/assets/scenes/world-map.webp | C5: 1816×866 | D5: P0 | E5: 已完成 | F5: 新增區域時要補標記位置
A6: 觀察圖鑑：台灣 3D 地圖貼圖 | B6: src/assets/scenes/map-tw.webp | C6: 1024×1536 | D6: P1 | E6: 已完成 | F6: GPT 畫，已簡化 30%
A7: 觀察圖鑑：日本 3D 地圖貼圖 | B7: src/assets/scenes/map-jp.webp | C7: 1254×1254 | D7: P1 | E7: 已完成 | F7: 中間只有富士山與立山連峰
A8: 之後新地區的 3D 地圖貼圖 | B8: src/assets/scenes/map-{地區}.webp | C8: 依地形 | D8: P2 | E8: 未開始 | F8: 用地形資料畫配置圖給 GPT 對位

Sheet 現有素材
A1: 現有素材盤點
A2: 2026-10-28 專案裡已經有的圖（不含程式畫的臨時圖）。
A4: 檔案 | B4: 用途 | C4: 尺寸 | D4: 大小（KB） | E4: 狀態
A5: src/assets/icons/coin.webp | B5: 金幣 | C5: 160×160 | D5: 8 | E5: 使用中
A6: src/assets/icons/gem.webp | B6: 寶石 | C6: 160×160 | D6: 6 | E6: 使用中
A7: src/assets/icons/chest-wood.webp | B7: 木箱 | C7: 512×512 | D7: 33.5 | E7: 使用中
A8: src/assets/icons/chest-green.webp | B8: 綠寶石箱 | C8: 512×512 | D8: 38.2 | E8: 使用中
A9: src/assets/icons/chest-royal.webp | B9: 紫金箱 | C9: 512×512 | D9: 49.2 | E9: 使用中
A10: src/assets/scenes/focus-done.webp | B10: 專注完成卡片；望遠鏡原型的暫代全景 | C10: 1697×927 | D10: 145.6 | E10: 使用中（暫代）
A11: src/assets/scenes/forest.webp | B11: 我的小島：森林 | C11: 1167×1347 | D11: 105 | E11: 使用中（暫代）
A12: src/assets/scenes/world-map.webp | B12: 區域切換的世界地圖 | C12: 1200×572 | D12: 89.5 | E12: 使用中
A13: src/assets/scenes/map-tw.webp | B13: 台灣 3D 地圖貼圖 | C13: 1024×1536 | D13: 101.4 | E13: 使用中
A14: src/assets/scenes/map-jp.webp | B14: 日本 3D 地圖貼圖 | C14: 1254×1254 | D14: 57 | E14: 使用中
A15: src/assets/animals/leopard_cat.webp | B15: 石虎成年主圖（靜態） | C15: 512×512 | D15: 29.5 | E15: 使用中
A16: public/icon-512.png | B16: App 圖示（舊） | C16: 512×512 | D16: 11.3 | E16: 暫代
... A19: src/assets/animals/mesh/leopard_cat/（12 個圖層） | B19: 石虎網格動態的圖層 | C19: 半尺寸 | D19: 67.5 | E19: 製作中（另一個對話接入中）

Sheet 交件檢查
A1: 交件檢查清單
A2: 每次交圖前逐項確認。
A4: 適用 | B4: 檢查項目 | C4: 確認
A5: 全部 | B5: 檔名照規則（英文小寫、底線、階段編號）
A6: 全部 | B6: 透明背景、sRGB；深色與淺色背景上都沒有白邊、殘留色塊
A7: 全部 | B7: 沒有文字、浮水印、地面陰影、背景物件
A8: 全部 | B8: 用手機實際顯示的大小檢查一次（縮小後線條、斷層最容易出現）
A9: 動物主圖 | B9: 正側面、頭朝右；腳底貼齊 y＝472（512 畫布，離下緣 40 px），水平置中
A10: 動物主圖 | B10: 三個成長階段畫布一樣大，幼年約成年的 60%、亞成年約 80%，腳底在同一條線
A11: 動物主圖 | B11: 三個階段看得出是同一種（毛色、斑紋、臉型一致）；縮到 30 px 仍認得出
A12: 動物動態 | B12: 靜止時網格圖層合成跟主圖比：平均差 ≤ 1.5、p99 ≤ 10
A13: 動物動態 | B13: 走路四個時間點、張望、低頭、張嘴、眨眼、甩尾兩端、耳朵最大角度，都用半尺寸貼圖放大檢查
A14: 動物動態 | B14: 在 Galaxy A8s 實機確認；每隻壓縮後 ≤ 120 KB
A15: 全景 | B15: 3000×1150 左右；動物停下的位置（62%, 59～70%）乾淨；夜晚版與白天版構圖完全一致
A16: 場景疊圖 | B16: 與底圖同畫布、完全對齊；6 個動物站位不被擋住
A17: 圖示 | B17: 512 px 置中、去背；縮到 24 px 仍清楚
